<?xml version="1.0"?>

<robot xmlns:sensor="http://playerstage.sourceforge.net/gazebo/xmlschema/#sensor"
       xmlns:controller="http://playerstage.sourceforge.net/gazebo/xmlschema/#controller"
       xmlns:interface="http://playerstage.sourceforge.net/gazebo/xmlschema/#interface"
       xmlns:xacro="http://www.ros.org/wiki/xacro">

	<link name="base_link"/>

<!-- Chassis -->
	<link name="chassis">
		<inertial>
			<mass value="20.0"/>
			<origin xyz="0 0 -0.090"/>
			<inertia ixx="0.3338" ixy="0.0" ixz="0.0"
				 iyy="0.4783" iyz="0.0"
				 izz="0.3338"/>
		</inertial>
		<visual>
			<origin xyz="0 0 0.0" rpy="0 0 0"/>
			<geometry name="pioneer_geom">
				<mesh filename="package://porthos_description/meshes/chassis.dae"/>
			</geometry>
			<material name="ChassisRed" />
		</visual>
		<collision>
			<origin xyz="0 0 0.0" rpy="0 0 0"/>
				<geometry>
					<mesh filename="package://porthos_description/meshes/chassis.dae"/>
				</geometry>
		</collision>
	</link>
	<gazebo reference="chassis">
		<material value="Gazebo/Red"/>
	</gazebo>
	<joint name="base_chassis_joint" type="fixed">
		<origin xyz="0.00 0 0.177" rpy="0 0 0"/>
		<parent link="base_link"/>
		<child link="chassis"/>
	</joint>

<!-- Top -->
	<link name="top_plate">
		<inertial>
			<mass value="0.1"/>	
			<origin xyz="-0.025 0 -0.223"/>
			<inertia ixx="1.0" ixy="0.0" ixz="0.0"
				 iyy="1.0" iyz="0.0"
 				izz="1.0"/>
		</inertial>
		<visual>
			<origin xyz="0 0 0" rpy="0 0 0"/>
			<geometry name="pioneer_geom">
				<mesh filename="package://porthos_description/meshes/top.dae"/>
			</geometry>
			<material name="TopBlack">
					<color rgba="0.038 0.038 0.038 1.0"/>
			</material>
		</visual>
		<collision>
			<origin xyz="0 0 0" rpy="0 0 0"/>
			<geometry>
				<box size="0 0 0"/>
			</geometry>
		</collision>
	</link>
	<gazebo reference="top_plate">
		<material value="Gazebo/Black"/>
	</gazebo>

	<joint name="chassis_top_joint" type="fixed">
		<origin xyz="0.043 0 0.254" rpy="0 0 0"/>
		<parent link="base_link"/>
		<child link="top_plate"/>
	</joint>
<!-- Front + Back Sonar -->
	<link name="front_sonar">
		<inertial>
			<mass value="0.1"/>	
			<origin xyz="0 0 0"/>
			<inertia ixx="1.0" ixy="0.0" ixz="0.0"
				 iyy="1.0" iyz="0.0" izz="1.0"/>
		</inertial>
		<visual name="front_sonar_visual">
			<origin xyz="0 0 0" rpy="0 0 0"/>
			<geometry name="pioneer_geom">
				<mesh filename="package://porthos_description/meshes/front_sonar.dae"/>
			</geometry>
			<material name="SonarYellow">
				<color rgba="0.715 0.583 0.210 1.0"/>
			</material>
		</visual>
		<collision>
			<origin xyz="0 0 0" rpy="0 0 0"/>
			<geometry>
				<box size="0 0 0"/>
			</geometry>
		</collision>
	</link>
	<gazebo reference="front_sonar">
		<material value="Gazebo/Yellow"/>
	</gazebo>

	<joint name="base_front_joint" type="fixed">
		<origin xyz="0.193 0 0.226" rpy="0 0 0"/>
		<parent link="base_link"/>
		<child link="front_sonar"/>
	</joint>

	<link name="back_sonar">
		<inertial>
			<mass value="0.1"/>	
			<origin xyz="0 0 0"/>
			<inertia ixx="1.0" ixy="0.0" ixz="0.0"
				 iyy="1.0" iyz="0.0" izz="1.0"/>
		</inertial>
		<visual name="back_sonar_visual">
			<origin xyz="0 0 0" rpy="0 0 0"/>
			<geometry name="pioneer_geom">
				<mesh filename="package://porthos_description/meshes/back_sonar.dae"/>
			</geometry>
			<material name="SonarYellow">
				<color rgba="0.715 0.583 0.210 1.0"/>
			</material>
		</visual>
		<collision>
			<origin xyz="0 0 0" rpy="0 0 0"/>
			<geometry>
				<box size="0 0 0"/>
			</geometry>
		</collision>
	</link>
	<gazebo reference="back_sonar">
		<material value="Gazebo/Yellow"/>
	</gazebo>

	<joint name="base_back_joint" type="fixed">
		<origin xyz="-0.193 0 0.226" rpy="0 0 0"/>
		<parent link="base_link"/>
		<child link="back_sonar"/>
	</joint>

<!-- Front Axles + Wheels + Hubcaps -->
<xacro:macro name="p3at_front" params="suffix reflect">
	<link name="p3at_front_${suffix}_axle">
		<inertial>
			<mass value="0.1"/>	
			<origin xyz="0 0 0"/>
			<inertia ixx="1.0" ixy="0.0" ixz="0.0"
				 iyy="1.0" iyz="0.0" izz="1.0"/>
  	 	</inertial>
	<visual>
		<origin xyz="0 0 0" rpy="0 0 0"/>
		<geometry name="pioneer_geom">
			<mesh filename="package://porthos_description/meshes/axle.dae"/>
		</geometry>
		<material name="AxleGrey">
			<color rgba="0.5 0.5 0.5 1"/>
		</material>
	</visual>
	<collision>
		<origin xyz="0 0 0" rpy="0 0 0"/>
		<geometry>
			<box size="0 0 0"/>
		</geometry>
	</collision>
	</link>
	<gazebo reference="p3at_front_${suffix}_axle">
		<material value="Gazebo/Grey"/>
	</gazebo>

	<joint name="base_front_${suffix}_axle_joint" type="fixed">
		<origin xyz="0.135 ${reflect*0.156} 0.111" rpy="0 0 0"/>
		<parent link="base_link"/>
		<child link="p3at_front_${suffix}_axle"/>
	</joint>

	<link name="p3at_front_${suffix}_hub">
		<inertial>
			<mass value="0.1"/>	
			<origin xyz="0 0 0"/>
			<inertia ixx="1.0" ixy="0.0" ixz="0.0"
				 iyy="1.0" iyz="0.0" izz="1.0"/>
  	 	</inertial>
	<visual>
		<origin xyz="0 0 0" rpy="0 0 0"/>
		<geometry name="pioneer_geom">
			<mesh filename="package://porthos_description/meshes/${suffix}_hubcap.dae"/>
		</geometry>
		<material name="HubcapYellow">
			<color rgba="1.0 0.811 0.151 1.0"/>
		</material>
	</visual>
	<collision>
		<origin xyz="0 0 0" rpy="0 0 0"/>
		<geometry>
			<box size="0 0 0"/>
		</geometry>
	</collision>
	</link>
	<gazebo reference="p3at_front_${suffix}_hub">
		<material value="Gazebo/Yellow"/>
	</gazebo>

	<joint name="base_front_${suffix}_hub_joint" type="fixed">
		<origin xyz="0 ${reflect*0.041} 0" rpy="0 0 0"/>
		<parent link="p3at_front_${suffix}_axle"/>
		<child link="p3at_front_${suffix}_hub"/>
	</joint>

	<link name="p3at_front_${suffix}_wheel">
		<inertial>
			<mass value="0.5"/>	
			<origin xyz="0 0 0"/>
			<inertia ixx="0.012411765597" ixy="0" ixz="0"
         iyy="0.015218160428" iyz="0" izz="0.011763977943"/>
      </inertial>
	<visual>
		<origin xyz="0 0 0" rpy="0 0 0"/>
		<geometry name="pioneer_geom">
			<mesh filename="package://porthos_description/meshes/wheel.dae"/>
		</geometry>
		<material name="WheelBlack">
			<color rgba="0.117 0.117 0.117 1"/>
		</material>
	</visual>
	<collision>
		<origin xyz="0 0 0" rpy="${-3.1415927/2} 0 0"/>
		<geometry>
	    <!--mesh filename="package://porthos_description/meshes/wheel.dae"/-->
	    <cylinder radius="0.110" length="0.035"/>
		</geometry>
	</collision>
	</link>
	<gazebo reference="p3at_front_${suffix}_wheel">
		<material value="Gazebo/Black"/>
	</gazebo>

	<joint name="p3at_front_${suffix}_wheel_joint" type="continuous">
  	<axis xyz="0 1 0"/>
    <anchor xyz="0 0 0"/>
    <limit effort="100" velocity="100" />
    <joint_properties damping="0.7"/>
		<origin xyz="0 0 0" rpy="0 0 0"/>
		<parent link="p3at_front_${suffix}_hub"/>
		<child link="p3at_front_${suffix}_wheel"/>
	</joint>
</xacro:macro>
<!-- Back Axles + Wheels + Hubcaps -->
<xacro:macro name="p3at_back" params="suffix reflect">
	<link name="p3at_back_${suffix}_axle">
		<inertial>
			<mass value="0.1"/>	
			<origin xyz="0 0 0"/>
			<inertia ixx="1.0" ixy="0.0" ixz="0.0"
				 iyy="1.0" iyz="0.0" izz="1.0"/>
  	 	</inertial>
	<visual>
		<origin xyz="0 0 0" rpy="0 0 0"/>
		<geometry name="pioneer_geom">
			<mesh filename="package://porthos_description/meshes/axle.dae"/>
		</geometry>
		<material name="AxleGrey">
			<color rgba="0.5 0.5 0.5 1"/>
		</material>
	</visual>
	<collision>
		<origin xyz="0 0 0" rpy="0 0 0"/>
		<geometry>
			<mesh filename="package://porthos_description/meshes/axle.dae"/>
		</geometry>
	</collision>
	</link>
	<gazebo reference="p3at_back_${suffix}_axle">
		<material value="Gazebo/Grey"/>
	</gazebo>

	<joint name="bp3at_back_${suffix}_axle_joint" type="fixed">
		<origin xyz="-0.134 ${reflect*0.156} 0.111" rpy="0 0 0"/>
		<parent link="base_link"/>
		<child link="p3at_back_${suffix}_axle"/>
	</joint>


	<link name="p3at_back_${suffix}_hub">
		<inertial>
			<mass value="0.1"/>	
			<origin xyz="0 0 0"/>
			<inertia ixx="1.0" ixy="0.0" ixz="0.0"
				 iyy="1.0" iyz="0.0" izz="1.0"/>
  	 	</inertial>
	<visual>
		<origin xyz="0 0 0" rpy="0 0 0"/>
		<geometry name="pioneer_geom">
			<mesh filename="package://porthos_description/meshes/${suffix}_hubcap.dae"/>
		</geometry>
		<material name="HubcapYellow"/>
	</visual>
	<collision>
		<origin xyz="0 0 0" rpy="0 0 0"/>
		<geometry>
			<mesh filename="package://porthos_description/meshes/${suffix}_hubcap.dae"/>
		</geometry>
	</collision>
	</link>
	<gazebo reference="p3at_back_${suffix}_hub">
		<material value="Gazebo/Yellow"/>
	</gazebo>

	<joint name="p3at_back_${suffix}_hub_joint" type="fixed">
		<origin xyz="-0 ${reflect*0.041} 0" rpy="0 0 0"/>
		<parent link="p3at_back_${suffix}_axle"/>
		<child link="p3at_back_${suffix}_hub"/>
	</joint>

	<link name="p3at_back_${suffix}_wheel">
		<inertial>
			<mass value="0.5"/>	
			<origin xyz="0 0 0"/>
			<inertia ixx="0.012411765597" ixy="0" ixz="0"
         iyy="0.015218160428" iyz="0" izz="0.011763977943"/>
      </inertial>
	<visual>
		<origin xyz="0 0 0" rpy="0 0 0"/>
		<geometry name="pioneer_geom">
			<mesh filename="package://porthos_description/meshes/wheel.dae"/>
		</geometry>
		<material name="WheelBlack"/>
	</visual>
	<collision>
		<origin xyz="0 0 0" rpy="${-3.1415927/2} 0 0"/>
		<geometry>
	    <!--mesh filename="package://porthos_description/meshes/wheel.dae"/-->
	    <cylinder radius="0.110" length="0.035"/>
		</geometry>
	</collision>
	</link>
	<gazebo reference="p3at_back_${suffix}_wheel">
		<material value="Gazebo/Black"/>
	</gazebo>

	<joint name="p3at_back_${suffix}_wheel_joint" type="continuous">
	  <axis xyz="0 1 0"/>
    <anchor xyz="0 0 0"/>
    <limit effort="100" velocity="100" />
    <joint_properties damping="0.7"/>
		<origin xyz="0 0 0" rpy="0 0 0"/>
		<parent link="p3at_back_${suffix}_hub"/>
		<child link="p3at_back_${suffix}_wheel"/>
	</joint>
	
  <gazebo reference="p3at_back_${suffix}_wheel">
    <kp>1000000.0</kp> <!-- kp and kd for rubber -->
    <kd>100.0</kd>
    <mu1>10.0</mu1>
    <mu2>0.1</mu2>
    <fdir1>1 0 0</fdir1> <!-- is this correct? -->
    <maxVel>1.0</maxVel>
    <minDepth>0.00</minDepth>
  </gazebo>
  
  <gazebo reference="p3at_front_${suffix}_wheel">
    <kp>1000000.0</kp> <!-- kp and kd for rubber -->
    <kd>100.0</kd>
    <mu1>10.0</mu1>
    <mu2>0.1</mu2>
    <fdir1>1 0 0</fdir1> <!-- is this correct? -->
    <maxVel>1.0</maxVel>
    <minDepth>0.00</minDepth>
  </gazebo>

</xacro:macro>


<xacro:macro name="p3at_gazebo_ext">

<gazebo>
    <plugin name="joint_state_publisher" filename="libgazebo_ros_joint_state_publisher.so">
      <robotNamespace></robotNamespace>
      <jointName>p3at_front_left_wheel_joint, p3at_front_right_wheel_joint, p3at_back_left_wheel_joint, p3at_back_right_wheel_joint</jointName>
      <updateRate>10.0</updateRate>
      <alwaysOn>true</alwaysOn>
    </plugin>
</gazebo>

<gazebo>
  <plugin name="skid_steer_drive_controller" filename="libgazebo_ros_skid_steer_drive.so">
    <updateRate>50.0</updateRate>
    <!-- <robotNamespace>/</robotNamespace> -->
    <leftFrontJoint>p3at_front_left_wheel_joint</leftFrontJoint>
    <rightFrontJoint>p3at_front_right_wheel_joint</rightFrontJoint>
    <leftRearJoint>p3at_back_left_wheel_joint</leftRearJoint>
    <rightRearJoint>p3at_back_right_wheel_joint</rightRearJoint>
    <odometryTopic>pose</odometryTopic>
    <wheelSeparation>0.4</wheelSeparation>
    <wheelDiameter>0.220</wheelDiameter>
    <covariance_x>1</covariance_x>
    <covariance_y>1</covariance_y>
    <covariance_yaw>1</covariance_yaw>
    <robotBaseFrame>base_link</robotBaseFrame>
    <commandTopic>cmd_vel</commandTopic>
    <odometryFrame>odom</odometryFrame>
    <broadcastTF>1</broadcastTF>
    <wheel_accel>1.8</wheel_accel>
    <torque>5</torque>
    <topicName>cmd_vel</topicName>
    <alpha1>0.001</alpha1>
    <alpha2>0.001</alpha2>
    <alpha3>0.001</alpha3>
    <alpha4>0.001</alpha4>
  </plugin>
</gazebo>

</xacro:macro>

</robot>
